<?xml version="1.0"?>

<robot xmlns:xacro="http://www.ros.org/wiki/xacro" 
    xmlns:sensor="http://playerstage.sourceforge.net/gazebo/xmlschema/#sensor"
        xmlns:controller="http://playerstage.sourceforge.net/gazebo/xmlschema/#controller"
        xmlns:interface="http://playerstage.sourceforge.net/gazebo/xmlschema/#interface"
    name="robot">
    <!-- args for 16 lines velodyne lidar -->
    <xacro:property name="M_PI" value="3.1415926535897931" />
    <xacro:property name="parent" value="base_link" />
    <xacro:property name="origin" value="base_link" />
    <xacro:property name="name" value="velodyne" />
    <xacro:property name="topic" value="/velodyne_points" />
    <xacro:property name="hz" value="10" />
    <xacro:property name="lasers" value="16" />
    <xacro:property name="samples" value="1875" />
    <xacro:property name="collision_range" value="0.3" />
    <xacro:property name="min_range" value="0.9" />
    <xacro:property name="max_range" value="130" />
    <xacro:property name="noise" value="0.008" />
    <xacro:property name="min_angle" value="-${M_PI}" />
    <xacro:property name="max_angle" value="${M_PI}" />
    <xacro:property name="gpu" value="false" />



    <xacro:property name="length_wheel" value="0.05" />
    <xacro:property name="radius_wheel" value="0.05" />
    <xacro:property name="camera_link" value="0.05" /> 
    <xacro:macro name="default_inertial" params="mass">
               <inertial>
                       <mass value="${mass}" />
                       <inertia ixx="1.0" ixy="0.0" ixz="0.0"
                                iyy="1.0" iyz="0.0"
                                izz="1.0" />
               </inertial>
    </xacro:macro>

    <link name="base_footprint">
        <visual>
            <geometry>
                    <box size="0.001 0.001 0.001"/>
                </geometry>
            <origin rpy="0 0 0" xyz="0 0 0"/>
        </visual>
        <xacro:default_inertial mass="0.0001"/>
    </link>
    <xacro:include filename="$(find delivery_robot_navigation)/urdf/delivery_robot.gazebo" />

    <gazebo reference="base_footprint">
        <material>Gazebo/Green</material>
        <turnGravityOff>false</turnGravityOff>
    </gazebo>

    <joint name="base_footprint_joint" type="fixed">
        <origin xyz="0 0 0" />
        <parent link="base_footprint" />
        <child link="base_link" />
    </joint>


    <link name="base_link">
        <visual>
            <geometry>
                    <box size="0.8 1.2 .4"/>
                </geometry>
            <origin rpy="0 0 1.54" xyz="0 0 0.2"/>
            <material name="white">
                <color rgba="1 1 1 1"/>
            </material>
        </visual>
        <collision>
            <geometry>
                    <box size="0.8 1.2 .4"/>
            </geometry>
        </collision>
        <xacro:default_inertial mass="10"/>
    </link>

    <link name="wheel_1">
        <visual>
                <geometry>
                    <cylinder length="${length_wheel}" radius="${radius_wheel}"/>
                </geometry>
            <!-- <origin rpy="0 1.5 0" xyz="0.1 0.1 0"/> -->
            <origin rpy="0 0 0" xyz="0 0 0"/>
            <material name="black">
                <color rgba="0 0 0 1"/>
            </material>
        </visual>
        <collision>
            <geometry>
                    <cylinder length="${length_wheel}" radius="${radius_wheel}"/>
            </geometry>
        </collision>
        <xacro:default_inertial mass="1"/>
    </link>

    <link name="wheel_2">
        <visual>
                <geometry>
                    <cylinder length="${length_wheel}" radius="${radius_wheel}"/>
                </geometry>
            <!-- <origin rpy="0 1.5 0" xyz="-0.1 0.1 0"/> -->
            <origin rpy="0 0 0" xyz="0 0 0"/>
            <material name="black"/>
        </visual>
        <collision>
            <geometry>
                    <cylinder length="${length_wheel}" radius="${radius_wheel}"/>
            </geometry>
        </collision>
        <xacro:default_inertial mass="1"/>

    </link>

    <link name="wheel_3">
        <visual>
                <geometry>
                    <cylinder length="${length_wheel}" radius="${radius_wheel}"/>
                </geometry>
            <!-- <origin rpy="0 1.5 0" xyz="0.1 -0.1 0"/> -->

            <origin rpy="0 0 0" xyz="0 0 0"/>
            <material name="black"/>
        </visual>
        <collision>
            <geometry>
                    <cylinder length="${length_wheel}" radius="${radius_wheel}"/>
            </geometry>
        </collision>
        <xacro:default_inertial mass="1"/>
    </link>

    <link name="wheel_4">
        <visual>
                <geometry>
                    <cylinder length="${length_wheel}" radius="${radius_wheel}"/>
                </geometry>
        <!--    <origin rpy="0 1.5 0" xyz="-0.1 -0.1 0"/> -->
            <origin rpy="0 0 0" xyz="0 0 0" />
            <material name="black"/>
        </visual>
        <collision>
            <geometry>
                    <cylinder length="${length_wheel}" radius="${radius_wheel}"/>
            </geometry>
        </collision>
        <xacro:default_inertial mass="1"/>

    </link>



 <joint name="base_to_wheel1" type="continuous">
   <parent link="base_link"/>
   <child link="wheel_1"/>
   <origin rpy="-1.5707 0 0" xyz="0.4 0.6 0"/>
   <axis xyz="0 0 1" />
 </joint>

 <joint name="base_to_wheel2" type="continuous">
   <axis xyz="0 0 1" />
   <anchor xyz="0 0 0" />
   <limit effort="100" velocity="100" />
   <parent link="base_link"/>
   <child link="wheel_2"/>
   <origin rpy="-1.5707 0 0" xyz="-0.4 0.6 0"/>
</joint>

 <joint name="base_to_wheel3" type="continuous">
   <parent link="base_link"/>
   <axis xyz="0 0 1" />
   <child link="wheel_3"/>
   <origin rpy="-1.5707 0 0" xyz="0.4 -0.6 0"/>
 </joint>

 <joint name="base_to_wheel4" type="continuous">
   <parent link="base_link"/>
   <axis xyz="0 0 1" />
   <child link="wheel_4"/>
   <origin rpy="-1.5707 0 0" xyz="-0.4 -0.6 0"/>
 </joint>

  <!-- Camera joint -->
  <joint name="camera_joint" type="fixed">
    <axis xyz="0 1 0" />
    <origin xyz="0.5 0 0.5" rpy="0 0 0"/>
    <parent link="base_link"/>
    <child link="camera_link"/>
  </joint>

  <!-- Camera link -->
  <link name="camera_link">
    <collision>
      <origin xyz="0 0 0" rpy="0 0 0"/>
      <geometry>
    <box size="0.2 0.2 0.2"/>
      </geometry>
    </collision>

    <visual>
      <origin xyz="0 0 0" rpy="0 0 0"/>
      <geometry>
        <box size="0.2 0.2 0.2"/>
      </geometry>
      <material name="red">
    <color rgba="1 0 0 1"/>
      </material>
    </visual>

    <inertial>
      <mass value="1e-5" />
      <origin xyz="0 0 0" rpy="0 0 0"/>
      <inertia ixx="1e-6" ixy="0" ixz="0" iyy="1e-6" iyz="0" izz="1e-6" />
    </inertial>
  </link>

  <!--16 lines velodyne lidar-->
  <joint name="${name}_base_mount_joint" type="fixed">
      <origin xyz="0.5 0 0.7" rpy="0 0 0"/>
      <parent link="${parent}"/>
      <child link="${name}_base_link"/>
  </joint>
  <link name="${name}_base_link">
      <inertial>
        <mass value="0.83"/>
        <origin xyz="0 0 0.03585"/>
        <inertia ixx="${(0.83 * (3.0*0.0516*0.0516 + 0.0717*0.0717)) / 12.0}" ixy="0" ixz="0"
          iyy="${(0.83 * (3.0*0.0516*0.0516 + 0.0717*0.0717)) / 12.0}" iyz="0"
          izz="${0.5 * 0.83 * (0.0516*0.0516)}"/>
      </inertial>
      <visual>
        <geometry>
          <mesh filename="package://delivery_robot_navigation/meshes/VLP16_base_1.dae" />
        </geometry>
      </visual>
      <visual>
        <geometry>
          <mesh filename="package://delivery_robot_navigation/meshes/VLP16_base_2.dae" />
        </geometry>
      </visual>
      <collision>
        <origin rpy="0 0 0" xyz="0 0 0.03585"/>
        <geometry>
          <cylinder radius="0.0516" length="0.0717"/>
        </geometry>
      </collision>
    </link>

    <joint name="${name}_base_scan_joint" type="fixed" >
      <origin xyz="0 0 0.0377" rpy="0 0 0" />
      <parent link="${name}_base_link" />
      <child link="${name}"/>
    </joint>

    <link name="${name}">
      <inertial>
        <mass value="0.01"/>
        <origin xyz="0 0 0"/>
        <inertia ixx="1e-7" ixy="0" ixz="0" iyy="1e-7" iyz="0" izz="1e-7"/>
      </inertial>
      <visual>
        <origin xyz="0 0 -0.0377" />
        <geometry>
          <mesh filename="package://delivery_robot_navigation/meshes/VLP16_scan.dae" />
        </geometry>
      </visual>
    </link>
  <!-- Gazebo requires the velodyne_gazebo_plugins package -->
    <gazebo reference="${name}">
      <xacro:if value="${gpu}">
        <sensor type="gpu_ray" name="${name}-VLP16">
          <pose>0 0 0 0 0 0</pose>
          <visualize>false</visualize>
          <update_rate>${hz}</update_rate>
          <ray>
            <scan>
              <horizontal>
                <samples>${samples}</samples>
                <resolution>1</resolution>
                <min_angle>${min_angle}</min_angle>
                <max_angle>${max_angle}</max_angle>
              </horizontal>
              <vertical>
                <samples>${lasers}</samples>
                <resolution>1</resolution>
                <min_angle>-${15.0*M_PI/180.0}</min_angle>
                <max_angle> ${15.0*M_PI/180.0}</max_angle>
              </vertical>
            </scan>
            <range>
              <min>${collision_range}</min>
              <max>${max_range+1}</max>
              <resolution>0.001</resolution>
            </range>
            <noise>
              <type>gaussian</type>
              <mean>0.0</mean>
              <stddev>0.0</stddev>
            </noise>
          </ray>
          <plugin name="gazebo_ros_laser_controller" filename="libgazebo_ros_velodyne_gpu_laser.so">
            <topicName>${topic}</topicName>
            <frameName>${name}</frameName>
            <min_range>${min_range}</min_range>
            <max_range>${max_range}</max_range>
            <gaussianNoise>${noise}</gaussianNoise>
          </plugin>
        </sensor>
      </xacro:if>
      <xacro:unless value="${gpu}">
        <sensor type="ray" name="${name}-VLP16">
          <pose>0 0 0 0 0 0</pose>
          <visualize>false</visualize>
          <update_rate>${hz}</update_rate>
          <ray>
            <scan>
              <horizontal>
                <samples>${samples}</samples>
                <resolution>1</resolution>
                <min_angle>${min_angle}</min_angle>
                <max_angle>${max_angle}</max_angle>
              </horizontal>
              <vertical>
                <samples>${lasers}</samples>
                <resolution>1</resolution>
                <min_angle>-${15.0*M_PI/180.0}</min_angle>
                <max_angle> ${15.0*M_PI/180.0}</max_angle>
              </vertical>
            </scan>
            <range>
              <min>${collision_range}</min>
              <max>${max_range+1}</max>
              <resolution>0.001</resolution>
            </range>
            <noise>
              <type>gaussian</type>
              <mean>0.0</mean>
              <stddev>0.0</stddev>
            </noise>
          </ray>
          <plugin name="gazebo_ros_laser_controller" filename="libgazebo_ros_velodyne_laser.so">
            <topicName>${topic}</topicName>
            <frameName>${name}</frameName>
            <min_range>${min_range}</min_range>
            <max_range>${max_range}</max_range>
            <gaussianNoise>${noise}</gaussianNoise>
          </plugin>
        </sensor>
      </xacro:unless>
    </gazebo>




  <!-- Hokuyo joint -->
  <joint name="hokuyo_joint" type="fixed">
    <origin xyz="0.5 0 0.9" rpy="0 0 0"/>
    <parent link="base_link"/>
    <axis xyz="0 1 0" />
    <child link="hokuyo_link"/>
  </joint>

  <!-- Hokuyo Laser link-->
  <link name="hokuyo_link">
    <collision>
      <origin xyz="0 0 0" rpy="0 0 0"/>
      <geometry>
    <box size="0.4 0.4 0.4"/>
      </geometry>
    </collision>

    <visual>
      <origin xyz="0 0 0" rpy="0 0 0"/>
      <geometry>   
	        <mesh filename="package://delivery_robot_navigation/meshes/hokuyo.dae"/>
      </geometry>
    </visual>

    <inertial>
      <mass value="1e-5" />
      <origin xyz="0 0 0" rpy="0 0 0"/>
      <inertia ixx="1e-6" ixy="0" ixz="0" iyy="1e-6" iyz="0" izz="1e-6" />
    </inertial>
  </link>

</robot>
